{
 "cells": [
  {
   "cell_type": "code",
   "execution_count": 1,
   "id": "225a99c8",
   "metadata": {},
   "outputs": [],
   "source": [
    "import numpy as np\n",
    "import matplotlib.pyplot as plt\n",
    "import tensorflow as tf\n",
    "from tensorflow.keras.datasets import cifar10\n",
    "from tensorflow.keras.models import Model,Sequential\n",
    "from tensorflow.keras.layers import Activation,Input,BatchNormalization,Flatten, Dense, Conv2D, MaxPool2D,GlobalAveragePooling2D,Dropout\n",
    "from tensorflow.keras.losses import CategoricalCrossentropy\n",
    "from tensorflow.keras.optimizers import Adam\n",
    "from tensorflow.keras.callbacks import EarlyStopping"
   ]
  },
  {
   "cell_type": "code",
   "execution_count": 2,
   "id": "76450b7a",
   "metadata": {},
   "outputs": [],
   "source": [
    "class BottleNeck(tf.keras.layers.Layer):\n",
    "\n",
    "    def __init__(self, num_filters, stride):\n",
    "        super(BottleNeck, self).__init__()\n",
    "\n",
    "        self.conv1 = Conv2D(filters = num_filters, kernel_size=(3,3), strides= (1,1), padding = 'same')\n",
    "\n",
    "        self.bn1 = BatchNormalization()\n",
    "\n",
    "        \n",
    "\n",
    "        self.conv2 = Conv2D(filters = num_filters, kernel_size=(3,3), strides= stride, padding = 'same')\n",
    "\n",
    "        self.bn2 = BatchNormalization()\n",
    "        \n",
    "\n",
    "        self.shortcut = Sequential()\n",
    "\n",
    "        self.shortcut.add(Conv2D(num_filters, kernel_size=(3,3), strides= stride, padding = 'same'))\n",
    "\n",
    "        self.shortcut.add(BatchNormalization())\n",
    "\n",
    "            \n",
    "\n",
    "    def call(self, inputs, training=None, **kwargs):\n",
    "\n",
    "        \n",
    "\n",
    "        x = self.conv1(inputs)\n",
    "\n",
    "        x = tf.nn.relu(self.bn1(x))\n",
    "\n",
    "        x = self.conv2(x)\n",
    "\n",
    "        x = tf.nn.relu(self.bn2(x))\n",
    "\n",
    "        output = tf.nn.relu(tf.keras.layers.add([self.shortcut(inputs), x]))\n",
    "\n",
    "        \n",
    "\n",
    "        return output\n"
   ]
  },
  {
   "cell_type": "code",
   "execution_count": 3,
   "id": "7d477c7e",
   "metadata": {},
   "outputs": [],
   "source": [
    "def _make_layer(num_filters, num_blocks, stride):\n",
    "\n",
    "    \n",
    "\n",
    "    res_block = Sequential()\n",
    "\n",
    "    res_block.add(BottleNeck(num_filters, stride=stride))\n",
    "\n",
    "    \n",
    "\n",
    "    for _ in range(1, num_blocks): # 1에서 시작해서 num_block 수만큼 반복\n",
    "\n",
    "        res_block.add(BottleNeck(num_filters, stride=1))\n",
    "\n",
    "    \n",
    "\n",
    "    return res_block\n"
   ]
  },
  {
   "cell_type": "code",
   "execution_count": 4,
   "id": "5b3030de",
   "metadata": {},
   "outputs": [],
   "source": [
    "#class 선언하면 위에 import한 거와는 별개로 전혀 연동이 안 되는 듯...\n",
    "\"\"\"\n",
    "Model: combines various layers to build a machine learning model\n",
    "Model이 있어야 compile, fit, evaluate, predict 등의 함수를 이용할 수 있다.\n",
    "\"\"\"\n",
    "\n",
    "class ResNet(tf.keras.Model):\n",
    "\n",
    "    def __init__(self, num_block, num_units=10):\n",
    "        super(ResNet,self).__init__()\n",
    "\n",
    "        \n",
    "\n",
    "        self.conv1 = Conv2D(filters=64,kernel_size=(7,7),strides=(2,2),padding='same')\n",
    "\n",
    "        self.bn1 = BatchNormalization()\n",
    "\n",
    "        \n",
    "\n",
    "        self.mp1 = MaxPool2D(pool_size = (3,3), strides=(2,2), padding='same')\n",
    "\n",
    "        self.bn2 = BatchNormalization()\n",
    "\n",
    "\n",
    "        self.bt1 = _make_layer(16, num_block[0], 1)\n",
    "\n",
    "        self.bt2 = _make_layer(32, num_block[1], 2)\n",
    "\n",
    "        self.bt3 = _make_layer(64, num_block[2], 2)\n",
    "\n",
    "        \n",
    "\n",
    "        self.av1 = GlobalAveragePooling2D()\n",
    "\n",
    "        self.flatten = Flatten()\n",
    "\n",
    "        self.ds1 = Dense(units=256,activation='relu')\n",
    "\n",
    "        self.ds2 = Dense(units=128,activation='relu')\n",
    "\n",
    "        self.ds3 = Dense(units=num_units,activation='softmax')\n",
    "\n",
    "        \n",
    "\n",
    "    def call(self, inputs, training=None, mask=None):\n",
    "\n",
    "        x = self.conv1(inputs)\n",
    "\n",
    "        x = self.bn1(x, training=training)\n",
    "\n",
    "        x = tf.nn.relu(x)\n",
    "\n",
    "        x = self.mp1(x)\n",
    "\n",
    "        x = self.bn2(x)\n",
    "\n",
    "        x = self.bt1(x, training=training)\n",
    "\n",
    "        x = self.bt2(x, training=training)\n",
    "\n",
    "        x = self.bt3(x, training=training)\n",
    "\n",
    "        x = self.av1(x)\n",
    "\n",
    "        x = self.flatten(x)\n",
    "\n",
    "        x = self.ds1(x)\n",
    "\n",
    "        x = self.ds2(x)\n",
    "\n",
    "        output = self.ds3(x)\n",
    "\n",
    "\n",
    "        return output\n",
    "\n",
    "\n",
    "def ResNet34():\n",
    "\n",
    "    return ResNet(num_block = [3,4,6,3])\n"
   ]
  },
  {
   "cell_type": "code",
   "execution_count": 5,
   "id": "4e5c9a93",
   "metadata": {},
   "outputs": [
    {
     "name": "stdout",
     "output_type": "stream",
     "text": [
      "WARNING:tensorflow:AutoGraph could not transform <bound method BottleNeck.call of <__main__.BottleNeck object at 0x000002D02156C588>> and will run it as-is.\n",
      "Please report this to the TensorFlow team. When filing the bug, set the verbosity to 10 (on Linux, `export AUTOGRAPH_VERBOSITY=10`) and attach the full output.\n",
      "Cause: No module named 'tensorflow_core.estimator'\n",
      "WARNING: AutoGraph could not transform <bound method BottleNeck.call of <__main__.BottleNeck object at 0x000002D02156C588>> and will run it as-is.\n",
      "Please report this to the TensorFlow team. When filing the bug, set the verbosity to 10 (on Linux, `export AUTOGRAPH_VERBOSITY=10`) and attach the full output.\n",
      "Cause: No module named 'tensorflow_core.estimator'\n",
      "WARNING:tensorflow:AutoGraph could not transform <bound method BottleNeck.call of <__main__.BottleNeck object at 0x000002D0215D1E48>> and will run it as-is.\n",
      "Please report this to the TensorFlow team. When filing the bug, set the verbosity to 10 (on Linux, `export AUTOGRAPH_VERBOSITY=10`) and attach the full output.\n",
      "Cause: No module named 'tensorflow_core.estimator'\n",
      "WARNING: AutoGraph could not transform <bound method BottleNeck.call of <__main__.BottleNeck object at 0x000002D0215D1E48>> and will run it as-is.\n",
      "Please report this to the TensorFlow team. When filing the bug, set the verbosity to 10 (on Linux, `export AUTOGRAPH_VERBOSITY=10`) and attach the full output.\n",
      "Cause: No module named 'tensorflow_core.estimator'\n",
      "WARNING:tensorflow:AutoGraph could not transform <bound method BottleNeck.call of <__main__.BottleNeck object at 0x000002D0215E1BC8>> and will run it as-is.\n",
      "Please report this to the TensorFlow team. When filing the bug, set the verbosity to 10 (on Linux, `export AUTOGRAPH_VERBOSITY=10`) and attach the full output.\n",
      "Cause: No module named 'tensorflow_core.estimator'\n",
      "WARNING: AutoGraph could not transform <bound method BottleNeck.call of <__main__.BottleNeck object at 0x000002D0215E1BC8>> and will run it as-is.\n",
      "Please report this to the TensorFlow team. When filing the bug, set the verbosity to 10 (on Linux, `export AUTOGRAPH_VERBOSITY=10`) and attach the full output.\n",
      "Cause: No module named 'tensorflow_core.estimator'\n",
      "WARNING:tensorflow:AutoGraph could not transform <bound method BottleNeck.call of <__main__.BottleNeck object at 0x000002D0215F2208>> and will run it as-is.\n",
      "Please report this to the TensorFlow team. When filing the bug, set the verbosity to 10 (on Linux, `export AUTOGRAPH_VERBOSITY=10`) and attach the full output.\n",
      "Cause: No module named 'tensorflow_core.estimator'\n",
      "WARNING: AutoGraph could not transform <bound method BottleNeck.call of <__main__.BottleNeck object at 0x000002D0215F2208>> and will run it as-is.\n",
      "Please report this to the TensorFlow team. When filing the bug, set the verbosity to 10 (on Linux, `export AUTOGRAPH_VERBOSITY=10`) and attach the full output.\n",
      "Cause: No module named 'tensorflow_core.estimator'\n",
      "WARNING:tensorflow:AutoGraph could not transform <bound method BottleNeck.call of <__main__.BottleNeck object at 0x000002D0215FEF08>> and will run it as-is.\n",
      "Please report this to the TensorFlow team. When filing the bug, set the verbosity to 10 (on Linux, `export AUTOGRAPH_VERBOSITY=10`) and attach the full output.\n",
      "Cause: No module named 'tensorflow_core.estimator'\n",
      "WARNING: AutoGraph could not transform <bound method BottleNeck.call of <__main__.BottleNeck object at 0x000002D0215FEF08>> and will run it as-is.\n",
      "Please report this to the TensorFlow team. When filing the bug, set the verbosity to 10 (on Linux, `export AUTOGRAPH_VERBOSITY=10`) and attach the full output.\n",
      "Cause: No module named 'tensorflow_core.estimator'\n",
      "WARNING:tensorflow:AutoGraph could not transform <bound method BottleNeck.call of <__main__.BottleNeck object at 0x000002D02160F948>> and will run it as-is.\n",
      "Please report this to the TensorFlow team. When filing the bug, set the verbosity to 10 (on Linux, `export AUTOGRAPH_VERBOSITY=10`) and attach the full output.\n",
      "Cause: No module named 'tensorflow_core.estimator'\n",
      "WARNING: AutoGraph could not transform <bound method BottleNeck.call of <__main__.BottleNeck object at 0x000002D02160F948>> and will run it as-is.\n",
      "Please report this to the TensorFlow team. When filing the bug, set the verbosity to 10 (on Linux, `export AUTOGRAPH_VERBOSITY=10`) and attach the full output.\n",
      "Cause: No module named 'tensorflow_core.estimator'\n",
      "WARNING:tensorflow:AutoGraph could not transform <bound method BottleNeck.call of <__main__.BottleNeck object at 0x000002D02161CD88>> and will run it as-is.\n",
      "Please report this to the TensorFlow team. When filing the bug, set the verbosity to 10 (on Linux, `export AUTOGRAPH_VERBOSITY=10`) and attach the full output.\n",
      "Cause: No module named 'tensorflow_core.estimator'\n",
      "WARNING: AutoGraph could not transform <bound method BottleNeck.call of <__main__.BottleNeck object at 0x000002D02161CD88>> and will run it as-is.\n",
      "Please report this to the TensorFlow team. When filing the bug, set the verbosity to 10 (on Linux, `export AUTOGRAPH_VERBOSITY=10`) and attach the full output.\n",
      "Cause: No module named 'tensorflow_core.estimator'\n",
      "WARNING:tensorflow:AutoGraph could not transform <bound method BottleNeck.call of <__main__.BottleNeck object at 0x000002D02162BE08>> and will run it as-is.\n",
      "Please report this to the TensorFlow team. When filing the bug, set the verbosity to 10 (on Linux, `export AUTOGRAPH_VERBOSITY=10`) and attach the full output.\n",
      "Cause: No module named 'tensorflow_core.estimator'\n",
      "WARNING: AutoGraph could not transform <bound method BottleNeck.call of <__main__.BottleNeck object at 0x000002D02162BE08>> and will run it as-is.\n",
      "Please report this to the TensorFlow team. When filing the bug, set the verbosity to 10 (on Linux, `export AUTOGRAPH_VERBOSITY=10`) and attach the full output.\n",
      "Cause: No module named 'tensorflow_core.estimator'\n",
      "WARNING:tensorflow:AutoGraph could not transform <bound method BottleNeck.call of <__main__.BottleNeck object at 0x000002D021639688>> and will run it as-is.\n",
      "Please report this to the TensorFlow team. When filing the bug, set the verbosity to 10 (on Linux, `export AUTOGRAPH_VERBOSITY=10`) and attach the full output.\n",
      "Cause: No module named 'tensorflow_core.estimator'\n",
      "WARNING: AutoGraph could not transform <bound method BottleNeck.call of <__main__.BottleNeck object at 0x000002D021639688>> and will run it as-is.\n",
      "Please report this to the TensorFlow team. When filing the bug, set the verbosity to 10 (on Linux, `export AUTOGRAPH_VERBOSITY=10`) and attach the full output.\n",
      "Cause: No module named 'tensorflow_core.estimator'\n",
      "WARNING:tensorflow:AutoGraph could not transform <bound method BottleNeck.call of <__main__.BottleNeck object at 0x000002D021645C08>> and will run it as-is.\n",
      "Please report this to the TensorFlow team. When filing the bug, set the verbosity to 10 (on Linux, `export AUTOGRAPH_VERBOSITY=10`) and attach the full output.\n",
      "Cause: No module named 'tensorflow_core.estimator'\n",
      "WARNING: AutoGraph could not transform <bound method BottleNeck.call of <__main__.BottleNeck object at 0x000002D021645C08>> and will run it as-is.\n",
      "Please report this to the TensorFlow team. When filing the bug, set the verbosity to 10 (on Linux, `export AUTOGRAPH_VERBOSITY=10`) and attach the full output.\n",
      "Cause: No module named 'tensorflow_core.estimator'\n",
      "WARNING:tensorflow:AutoGraph could not transform <bound method BottleNeck.call of <__main__.BottleNeck object at 0x000002D021652D88>> and will run it as-is.\n",
      "Please report this to the TensorFlow team. When filing the bug, set the verbosity to 10 (on Linux, `export AUTOGRAPH_VERBOSITY=10`) and attach the full output.\n",
      "Cause: No module named 'tensorflow_core.estimator'\n",
      "WARNING: AutoGraph could not transform <bound method BottleNeck.call of <__main__.BottleNeck object at 0x000002D021652D88>> and will run it as-is.\n",
      "Please report this to the TensorFlow team. When filing the bug, set the verbosity to 10 (on Linux, `export AUTOGRAPH_VERBOSITY=10`) and attach the full output.\n",
      "Cause: No module named 'tensorflow_core.estimator'\n",
      "WARNING:tensorflow:AutoGraph could not transform <bound method BottleNeck.call of <__main__.BottleNeck object at 0x000002D021660E08>> and will run it as-is.\n",
      "Please report this to the TensorFlow team. When filing the bug, set the verbosity to 10 (on Linux, `export AUTOGRAPH_VERBOSITY=10`) and attach the full output.\n",
      "Cause: No module named 'tensorflow_core.estimator'\n"
     ]
    },
    {
     "name": "stdout",
     "output_type": "stream",
     "text": [
      "WARNING: AutoGraph could not transform <bound method BottleNeck.call of <__main__.BottleNeck object at 0x000002D021660E08>> and will run it as-is.\n",
      "Please report this to the TensorFlow team. When filing the bug, set the verbosity to 10 (on Linux, `export AUTOGRAPH_VERBOSITY=10`) and attach the full output.\n",
      "Cause: No module named 'tensorflow_core.estimator'\n",
      "WARNING:tensorflow:AutoGraph could not transform <bound method BottleNeck.call of <__main__.BottleNeck object at 0x000002D02166EB08>> and will run it as-is.\n",
      "Please report this to the TensorFlow team. When filing the bug, set the verbosity to 10 (on Linux, `export AUTOGRAPH_VERBOSITY=10`) and attach the full output.\n",
      "Cause: No module named 'tensorflow_core.estimator'\n",
      "WARNING: AutoGraph could not transform <bound method BottleNeck.call of <__main__.BottleNeck object at 0x000002D02166EB08>> and will run it as-is.\n",
      "Please report this to the TensorFlow team. When filing the bug, set the verbosity to 10 (on Linux, `export AUTOGRAPH_VERBOSITY=10`) and attach the full output.\n",
      "Cause: No module named 'tensorflow_core.estimator'\n",
      "Model: \"res_net\"\n",
      "_________________________________________________________________\n",
      "Layer (type)                 Output Shape              Param #   \n",
      "=================================================================\n",
      "conv2d (Conv2D)              multiple                  9472      \n",
      "_________________________________________________________________\n",
      "batch_normalization (BatchNo multiple                  256       \n",
      "_________________________________________________________________\n",
      "max_pooling2d (MaxPooling2D) multiple                  0         \n",
      "_________________________________________________________________\n",
      "batch_normalization_1 (Batch multiple                  256       \n",
      "_________________________________________________________________\n",
      "sequential (Sequential)      multiple                  35280     \n",
      "_________________________________________________________________\n",
      "sequential_4 (Sequential)    multiple                  103296    \n",
      "_________________________________________________________________\n",
      "sequential_9 (Sequential)    multiple                  632448    \n",
      "_________________________________________________________________\n",
      "global_average_pooling2d (Gl multiple                  0         \n",
      "_________________________________________________________________\n",
      "flatten (Flatten)            multiple                  0         \n",
      "_________________________________________________________________\n",
      "dense (Dense)                multiple                  16640     \n",
      "_________________________________________________________________\n",
      "dense_1 (Dense)              multiple                  32896     \n",
      "_________________________________________________________________\n",
      "dense_2 (Dense)              multiple                  1290      \n",
      "=================================================================\n",
      "Total params: 831,834\n",
      "Trainable params: 828,218\n",
      "Non-trainable params: 3,616\n",
      "_________________________________________________________________\n"
     ]
    }
   ],
   "source": [
    "def get_model():\n",
    "\n",
    "    model = ResNet34()\n",
    "\n",
    "    model.build(input_shape=(None,32,32,3))\n",
    "\n",
    "    model.summary()\n",
    "\n",
    "    return model\n",
    "\n",
    "\n",
    "model = get_model()\n"
   ]
  },
  {
   "cell_type": "code",
   "execution_count": 6,
   "id": "dbdce6b4",
   "metadata": {},
   "outputs": [],
   "source": [
    "def load_cifar10_dataset():\n",
    "    (train_validation_images, train_validation_labels), (test_images, test_labels) \\\n",
    "    = cifar10.load_data()\n",
    "    \n",
    "    train_validation_images = train_validation_images / 255\n",
    "    test_images = test_images / 255.\n",
    "    \n",
    "    n_train_validation = train_validation_images.shape[0]\n",
    "    train_ratio = 0.8\n",
    "    n_train = int(n_train_validation * train_ratio)\n",
    "    \n",
    "    train_x = train_validation_images[:n_train]\n",
    "    train_y = train_validation_labels[:n_train]\n",
    "    validation_x = train_validation_images[n_train:]\n",
    "    validation_y = train_validation_labels[n_train:]\n",
    "    test_x = test_images\n",
    "    test_y = test_labels\n",
    "    \n",
    "    print('Train set')\n",
    "    print('Image :', train_x.shape)\n",
    "    print('Label :', train_y.shape)\n",
    "    print('Validation set')\n",
    "    print('Image :', validation_x.shape)\n",
    "    print('Label :', validation_y.shape)\n",
    "    print('Train & validation set')\n",
    "    print('Image :', test_x.shape)\n",
    "    print('Label :', test_y.shape)\n",
    "    \n",
    "    return train_x, train_y, validation_x, validation_y, test_x, test_y"
   ]
  },
  {
   "cell_type": "code",
   "execution_count": 7,
   "id": "2b1c6034",
   "metadata": {},
   "outputs": [
    {
     "name": "stdout",
     "output_type": "stream",
     "text": [
      "Train set\n",
      "Image : (40000, 32, 32, 3)\n",
      "Label : (40000, 1)\n",
      "Validation set\n",
      "Image : (10000, 32, 32, 3)\n",
      "Label : (10000, 1)\n",
      "Train & validation set\n",
      "Image : (10000, 32, 32, 3)\n",
      "Label : (10000, 1)\n"
     ]
    }
   ],
   "source": [
    "train_x, train_y, validation_x, validation_y, test_x, test_y = load_cifar10_dataset()\n",
    "\n",
    "\n",
    "train_y = tf.keras.utils.to_categorical(train_y,10)\n",
    "\n",
    "validation_y = tf.keras.utils.to_categorical(validation_y,10)\n",
    "\n",
    "test_y = tf.keras.utils.to_categorical(test_y,10)"
   ]
  },
  {
   "cell_type": "code",
   "execution_count": null,
   "id": "2eafdd39",
   "metadata": {},
   "outputs": [
    {
     "name": "stdout",
     "output_type": "stream",
     "text": [
      "ERROR! Session/line number was not unique in database. History logging moved to new session 109\n",
      "Train on 40000 samples, validate on 10000 samples\n",
      "Epoch 1/50\n",
      "   32/40000 [..............................] - ETA: 1:13:03"
     ]
    },
    {
     "name": "stderr",
     "output_type": "stream",
     "text": [
      "ERROR:root:Internal Python error in the inspect module.\n",
      "Below is the traceback from this internal error.\n",
      "\n",
      "ERROR:root:Internal Python error in the inspect module.\n",
      "Below is the traceback from this internal error.\n",
      "\n",
      "ERROR:root:Internal Python error in the inspect module.\n",
      "Below is the traceback from this internal error.\n",
      "\n"
     ]
    },
    {
     "name": "stdout",
     "output_type": "stream",
     "text": [
      "Traceback (most recent call last):\n",
      "  File \"C:\\Users\\tlsdu\\anaconda3\\envs\\mine\\lib\\site-packages\\IPython\\core\\interactiveshell.py\", line 3457, in run_code\n",
      "    exec(code_obj, self.user_global_ns, self.user_ns)\n",
      "  File \"C:\\Users\\tlsdu\\AppData\\Local\\Temp\\ipykernel_12152\\567259730.py\", line 2, in <module>\n",
      "    history = model.fit(train_x, train_y, epochs=50, batch_size=32,validation_data=(validation_x, validation_y))\n",
      "  File \"C:\\Users\\tlsdu\\anaconda3\\envs\\mine\\lib\\site-packages\\tensorflow_core\\python\\keras\\engine\\training.py\", line 819, in fit\n",
      "    use_multiprocessing=use_multiprocessing)\n",
      "  File \"C:\\Users\\tlsdu\\anaconda3\\envs\\mine\\lib\\site-packages\\tensorflow_core\\python\\keras\\engine\\training_v2.py\", line 342, in fit\n",
      "    total_epochs=epochs)\n",
      "  File \"C:\\Users\\tlsdu\\anaconda3\\envs\\mine\\lib\\site-packages\\tensorflow_core\\python\\keras\\engine\\training_v2.py\", line 128, in run_one_epoch\n",
      "    batch_outs = execution_function(iterator)\n",
      "  File \"C:\\Users\\tlsdu\\anaconda3\\envs\\mine\\lib\\site-packages\\tensorflow_core\\python\\keras\\engine\\training_v2_utils.py\", line 98, in execution_function\n",
      "    distributed_function(input_fn))\n",
      "  File \"C:\\Users\\tlsdu\\anaconda3\\envs\\mine\\lib\\site-packages\\tensorflow_core\\python\\eager\\def_function.py\", line 568, in __call__\n",
      "    result = self._call(*args, **kwds)\n",
      "  File \"C:\\Users\\tlsdu\\anaconda3\\envs\\mine\\lib\\site-packages\\tensorflow_core\\python\\eager\\def_function.py\", line 632, in _call\n",
      "    return self._stateless_fn(*args, **kwds)\n",
      "  File \"C:\\Users\\tlsdu\\anaconda3\\envs\\mine\\lib\\site-packages\\tensorflow_core\\python\\eager\\function.py\", line 2363, in __call__\n",
      "    return graph_function._filtered_call(args, kwargs)  # pylint: disable=protected-access\n",
      "  File \"C:\\Users\\tlsdu\\anaconda3\\envs\\mine\\lib\\site-packages\\tensorflow_core\\python\\eager\\function.py\", line 1611, in _filtered_call\n",
      "    self.captured_inputs)\n",
      "  File \"C:\\Users\\tlsdu\\anaconda3\\envs\\mine\\lib\\site-packages\\tensorflow_core\\python\\eager\\function.py\", line 1692, in _call_flat\n",
      "    ctx, args, cancellation_manager=cancellation_manager))\n",
      "  File \"C:\\Users\\tlsdu\\anaconda3\\envs\\mine\\lib\\site-packages\\tensorflow_core\\python\\eager\\function.py\", line 545, in call\n",
      "    ctx=ctx)\n",
      "  File \"C:\\Users\\tlsdu\\anaconda3\\envs\\mine\\lib\\site-packages\\tensorflow_core\\python\\eager\\execute.py\", line 67, in quick_execute\n",
      "    six.raise_from(core._status_to_exception(e.code, message), None)\n",
      "  File \"<string>\", line 3, in raise_from\n",
      "tensorflow.python.framework.errors_impl.UnknownError:  Failed to get convolution algorithm. This is probably because cuDNN failed to initialize, so try looking to see if a warning log message was printed above.\n",
      "\t [[node res_net/conv2d/Conv2D (defined at \\AppData\\Local\\Temp\\ipykernel_12152\\2408022449.py:47) ]] [Op:__inference_distributed_function_22855]\n",
      "\n",
      "Errors may have originated from an input operation.\n",
      "Input Source operations connected to node res_net/conv2d/Conv2D:\n",
      " Cast (defined at \\AppData\\Local\\Temp\\ipykernel_12152\\567259730.py:2)\n",
      "\n",
      "Function call stack:\n",
      "distributed_function\n",
      "\n",
      "\n",
      "During handling of the above exception, another exception occurred:\n",
      "\n",
      "Traceback (most recent call last):\n",
      "  File \"C:\\Users\\tlsdu\\anaconda3\\envs\\mine\\lib\\site-packages\\IPython\\core\\interactiveshell.py\", line 2077, in showtraceback\n",
      "    stb = value._render_traceback_()\n",
      "AttributeError: 'UnknownError' object has no attribute '_render_traceback_'\n",
      "\n",
      "During handling of the above exception, another exception occurred:\n",
      "\n",
      "Traceback (most recent call last):\n",
      "  File \"C:\\Users\\tlsdu\\anaconda3\\envs\\mine\\lib\\site-packages\\IPython\\core\\ultratb.py\", line 1101, in get_records\n",
      "    return _fixed_getinnerframes(etb, number_of_lines_of_context, tb_offset)\n",
      "  File \"C:\\Users\\tlsdu\\anaconda3\\envs\\mine\\lib\\site-packages\\IPython\\core\\ultratb.py\", line 248, in wrapped\n",
      "    return f(*args, **kwargs)\n",
      "  File \"C:\\Users\\tlsdu\\anaconda3\\envs\\mine\\lib\\site-packages\\IPython\\core\\ultratb.py\", line 281, in _fixed_getinnerframes\n",
      "    records = fix_frame_records_filenames(inspect.getinnerframes(etb, context))\n",
      "  File \"C:\\Users\\tlsdu\\anaconda3\\envs\\mine\\lib\\inspect.py\", line 1502, in getinnerframes\n",
      "    frameinfo = (tb.tb_frame,) + getframeinfo(tb, context)\n",
      "  File \"C:\\Users\\tlsdu\\anaconda3\\envs\\mine\\lib\\inspect.py\", line 1460, in getframeinfo\n",
      "    filename = getsourcefile(frame) or getfile(frame)\n",
      "  File \"C:\\Users\\tlsdu\\anaconda3\\envs\\mine\\lib\\inspect.py\", line 696, in getsourcefile\n",
      "    if getattr(getmodule(object, filename), '__loader__', None) is not None:\n",
      "  File \"C:\\Users\\tlsdu\\anaconda3\\envs\\mine\\lib\\inspect.py\", line 733, in getmodule\n",
      "    if ismodule(module) and hasattr(module, '__file__'):\n",
      "  File \"C:\\Users\\tlsdu\\anaconda3\\envs\\mine\\lib\\site-packages\\tensorflow\\__init__.py\", line 50, in __getattr__\n",
      "    module = self._load()\n",
      "  File \"C:\\Users\\tlsdu\\anaconda3\\envs\\mine\\lib\\site-packages\\tensorflow\\__init__.py\", line 44, in _load\n",
      "    module = _importlib.import_module(self.__name__)\n",
      "  File \"C:\\Users\\tlsdu\\anaconda3\\envs\\mine\\lib\\importlib\\__init__.py\", line 127, in import_module\n",
      "    return _bootstrap._gcd_import(name[level:], package, level)\n",
      "  File \"<frozen importlib._bootstrap>\", line 1006, in _gcd_import\n",
      "  File \"<frozen importlib._bootstrap>\", line 983, in _find_and_load\n",
      "  File \"<frozen importlib._bootstrap>\", line 965, in _find_and_load_unlocked\n",
      "ModuleNotFoundError: No module named 'tensorflow_core.estimator'\n",
      "Traceback (most recent call last):\n",
      "  File \"C:\\Users\\tlsdu\\anaconda3\\envs\\mine\\lib\\site-packages\\IPython\\core\\interactiveshell.py\", line 3457, in run_code\n",
      "    exec(code_obj, self.user_global_ns, self.user_ns)\n",
      "  File \"C:\\Users\\tlsdu\\AppData\\Local\\Temp\\ipykernel_12152\\567259730.py\", line 2, in <module>\n",
      "    history = model.fit(train_x, train_y, epochs=50, batch_size=32,validation_data=(validation_x, validation_y))\n",
      "  File \"C:\\Users\\tlsdu\\anaconda3\\envs\\mine\\lib\\site-packages\\tensorflow_core\\python\\keras\\engine\\training.py\", line 819, in fit\n",
      "    use_multiprocessing=use_multiprocessing)\n",
      "  File \"C:\\Users\\tlsdu\\anaconda3\\envs\\mine\\lib\\site-packages\\tensorflow_core\\python\\keras\\engine\\training_v2.py\", line 342, in fit\n",
      "    total_epochs=epochs)\n",
      "  File \"C:\\Users\\tlsdu\\anaconda3\\envs\\mine\\lib\\site-packages\\tensorflow_core\\python\\keras\\engine\\training_v2.py\", line 128, in run_one_epoch\n",
      "    batch_outs = execution_function(iterator)\n",
      "  File \"C:\\Users\\tlsdu\\anaconda3\\envs\\mine\\lib\\site-packages\\tensorflow_core\\python\\keras\\engine\\training_v2_utils.py\", line 98, in execution_function\n",
      "    distributed_function(input_fn))\n",
      "  File \"C:\\Users\\tlsdu\\anaconda3\\envs\\mine\\lib\\site-packages\\tensorflow_core\\python\\eager\\def_function.py\", line 568, in __call__\n",
      "    result = self._call(*args, **kwds)\n",
      "  File \"C:\\Users\\tlsdu\\anaconda3\\envs\\mine\\lib\\site-packages\\tensorflow_core\\python\\eager\\def_function.py\", line 632, in _call\n",
      "    return self._stateless_fn(*args, **kwds)\n",
      "  File \"C:\\Users\\tlsdu\\anaconda3\\envs\\mine\\lib\\site-packages\\tensorflow_core\\python\\eager\\function.py\", line 2363, in __call__\n",
      "    return graph_function._filtered_call(args, kwargs)  # pylint: disable=protected-access\n",
      "  File \"C:\\Users\\tlsdu\\anaconda3\\envs\\mine\\lib\\site-packages\\tensorflow_core\\python\\eager\\function.py\", line 1611, in _filtered_call\n",
      "    self.captured_inputs)\n",
      "  File \"C:\\Users\\tlsdu\\anaconda3\\envs\\mine\\lib\\site-packages\\tensorflow_core\\python\\eager\\function.py\", line 1692, in _call_flat\n",
      "    ctx, args, cancellation_manager=cancellation_manager))\n",
      "  File \"C:\\Users\\tlsdu\\anaconda3\\envs\\mine\\lib\\site-packages\\tensorflow_core\\python\\eager\\function.py\", line 545, in call\n",
      "    ctx=ctx)\n",
      "  File \"C:\\Users\\tlsdu\\anaconda3\\envs\\mine\\lib\\site-packages\\tensorflow_core\\python\\eager\\execute.py\", line 67, in quick_execute\n",
      "    six.raise_from(core._status_to_exception(e.code, message), None)\n",
      "  File \"<string>\", line 3, in raise_from\n",
      "tensorflow.python.framework.errors_impl.UnknownError:  Failed to get convolution algorithm. This is probably because cuDNN failed to initialize, so try looking to see if a warning log message was printed above.\n",
      "\t [[node res_net/conv2d/Conv2D (defined at \\AppData\\Local\\Temp\\ipykernel_12152\\2408022449.py:47) ]] [Op:__inference_distributed_function_22855]\n",
      "\n",
      "Errors may have originated from an input operation.\n",
      "Input Source operations connected to node res_net/conv2d/Conv2D:\n",
      " Cast (defined at \\AppData\\Local\\Temp\\ipykernel_12152\\567259730.py:2)\n",
      "\n",
      "Function call stack:\n",
      "distributed_function\n",
      "\n",
      "\n",
      "During handling of the above exception, another exception occurred:\n",
      "\n",
      "Traceback (most recent call last):\n",
      "  File \"C:\\Users\\tlsdu\\anaconda3\\envs\\mine\\lib\\site-packages\\IPython\\core\\interactiveshell.py\", line 2077, in showtraceback\n",
      "    stb = value._render_traceback_()\n",
      "AttributeError: 'UnknownError' object has no attribute '_render_traceback_'\n",
      "\n",
      "During handling of the above exception, another exception occurred:\n",
      "\n",
      "Traceback (most recent call last):\n",
      "  File \"C:\\Users\\tlsdu\\anaconda3\\envs\\mine\\lib\\site-packages\\IPython\\core\\interactiveshell.py\", line 3377, in run_ast_nodes\n",
      "    if (await self.run_code(code, result,  async_=asy)):\n",
      "  File \"C:\\Users\\tlsdu\\anaconda3\\envs\\mine\\lib\\site-packages\\IPython\\core\\interactiveshell.py\", line 3474, in run_code\n",
      "    self.showtraceback(running_compiled_code=True)\n",
      "  File \"C:\\Users\\tlsdu\\anaconda3\\envs\\mine\\lib\\site-packages\\IPython\\core\\interactiveshell.py\", line 2080, in showtraceback\n",
      "    value, tb, tb_offset=tb_offset)\n",
      "  File \"C:\\Users\\tlsdu\\anaconda3\\envs\\mine\\lib\\site-packages\\IPython\\core\\ultratb.py\", line 1368, in structured_traceback\n",
      "    self, etype, value, tb, tb_offset, number_of_lines_of_context)\n",
      "  File \"C:\\Users\\tlsdu\\anaconda3\\envs\\mine\\lib\\site-packages\\IPython\\core\\ultratb.py\", line 1268, in structured_traceback\n",
      "    self, etype, value, tb, tb_offset, number_of_lines_of_context\n",
      "  File \"C:\\Users\\tlsdu\\anaconda3\\envs\\mine\\lib\\site-packages\\IPython\\core\\ultratb.py\", line 1125, in structured_traceback\n",
      "    tb_offset)\n",
      "  File \"C:\\Users\\tlsdu\\anaconda3\\envs\\mine\\lib\\site-packages\\IPython\\core\\ultratb.py\", line 1082, in format_exception_as_a_whole\n",
      "    last_unique, recursion_repeat = find_recursion(orig_etype, evalue, records)\n",
      "  File \"C:\\Users\\tlsdu\\anaconda3\\envs\\mine\\lib\\site-packages\\IPython\\core\\ultratb.py\", line 382, in find_recursion\n",
      "    return len(records), 0\n",
      "TypeError: object of type 'NoneType' has no len()\n",
      "\n",
      "During handling of the above exception, another exception occurred:\n",
      "\n",
      "Traceback (most recent call last):\n",
      "  File \"C:\\Users\\tlsdu\\anaconda3\\envs\\mine\\lib\\site-packages\\IPython\\core\\interactiveshell.py\", line 2077, in showtraceback\n",
      "    stb = value._render_traceback_()\n",
      "AttributeError: 'TypeError' object has no attribute '_render_traceback_'\n",
      "\n",
      "During handling of the above exception, another exception occurred:\n",
      "\n",
      "Traceback (most recent call last):\n",
      "  File \"C:\\Users\\tlsdu\\anaconda3\\envs\\mine\\lib\\site-packages\\IPython\\core\\ultratb.py\", line 1101, in get_records\n",
      "    return _fixed_getinnerframes(etb, number_of_lines_of_context, tb_offset)\n",
      "  File \"C:\\Users\\tlsdu\\anaconda3\\envs\\mine\\lib\\site-packages\\IPython\\core\\ultratb.py\", line 248, in wrapped\n",
      "    return f(*args, **kwargs)\n",
      "  File \"C:\\Users\\tlsdu\\anaconda3\\envs\\mine\\lib\\site-packages\\IPython\\core\\ultratb.py\", line 281, in _fixed_getinnerframes\n",
      "    records = fix_frame_records_filenames(inspect.getinnerframes(etb, context))\n",
      "  File \"C:\\Users\\tlsdu\\anaconda3\\envs\\mine\\lib\\inspect.py\", line 1502, in getinnerframes\n",
      "    frameinfo = (tb.tb_frame,) + getframeinfo(tb, context)\n",
      "  File \"C:\\Users\\tlsdu\\anaconda3\\envs\\mine\\lib\\inspect.py\", line 1460, in getframeinfo\n",
      "    filename = getsourcefile(frame) or getfile(frame)\n",
      "  File \"C:\\Users\\tlsdu\\anaconda3\\envs\\mine\\lib\\inspect.py\", line 696, in getsourcefile\n",
      "    if getattr(getmodule(object, filename), '__loader__', None) is not None:\n",
      "  File \"C:\\Users\\tlsdu\\anaconda3\\envs\\mine\\lib\\inspect.py\", line 733, in getmodule\n",
      "    if ismodule(module) and hasattr(module, '__file__'):\n",
      "  File \"C:\\Users\\tlsdu\\anaconda3\\envs\\mine\\lib\\site-packages\\tensorflow\\__init__.py\", line 50, in __getattr__\n",
      "    module = self._load()\n",
      "  File \"C:\\Users\\tlsdu\\anaconda3\\envs\\mine\\lib\\site-packages\\tensorflow\\__init__.py\", line 44, in _load\n",
      "    module = _importlib.import_module(self.__name__)\n",
      "  File \"C:\\Users\\tlsdu\\anaconda3\\envs\\mine\\lib\\importlib\\__init__.py\", line 127, in import_module\n",
      "    return _bootstrap._gcd_import(name[level:], package, level)\n",
      "  File \"<frozen importlib._bootstrap>\", line 1006, in _gcd_import\n",
      "  File \"<frozen importlib._bootstrap>\", line 983, in _find_and_load\n",
      "  File \"<frozen importlib._bootstrap>\", line 965, in _find_and_load_unlocked\n",
      "ModuleNotFoundError: No module named 'tensorflow_core.estimator'\n",
      "Traceback (most recent call last):\n",
      "  File \"C:\\Users\\tlsdu\\anaconda3\\envs\\mine\\lib\\site-packages\\IPython\\core\\interactiveshell.py\", line 3457, in run_code\n",
      "    exec(code_obj, self.user_global_ns, self.user_ns)\n",
      "  File \"C:\\Users\\tlsdu\\AppData\\Local\\Temp\\ipykernel_12152\\567259730.py\", line 2, in <module>\n",
      "    history = model.fit(train_x, train_y, epochs=50, batch_size=32,validation_data=(validation_x, validation_y))\n",
      "  File \"C:\\Users\\tlsdu\\anaconda3\\envs\\mine\\lib\\site-packages\\tensorflow_core\\python\\keras\\engine\\training.py\", line 819, in fit\n",
      "    use_multiprocessing=use_multiprocessing)\n",
      "  File \"C:\\Users\\tlsdu\\anaconda3\\envs\\mine\\lib\\site-packages\\tensorflow_core\\python\\keras\\engine\\training_v2.py\", line 342, in fit\n",
      "    total_epochs=epochs)\n",
      "  File \"C:\\Users\\tlsdu\\anaconda3\\envs\\mine\\lib\\site-packages\\tensorflow_core\\python\\keras\\engine\\training_v2.py\", line 128, in run_one_epoch\n",
      "    batch_outs = execution_function(iterator)\n",
      "  File \"C:\\Users\\tlsdu\\anaconda3\\envs\\mine\\lib\\site-packages\\tensorflow_core\\python\\keras\\engine\\training_v2_utils.py\", line 98, in execution_function\n",
      "    distributed_function(input_fn))\n",
      "  File \"C:\\Users\\tlsdu\\anaconda3\\envs\\mine\\lib\\site-packages\\tensorflow_core\\python\\eager\\def_function.py\", line 568, in __call__\n",
      "    result = self._call(*args, **kwds)\n",
      "  File \"C:\\Users\\tlsdu\\anaconda3\\envs\\mine\\lib\\site-packages\\tensorflow_core\\python\\eager\\def_function.py\", line 632, in _call\n",
      "    return self._stateless_fn(*args, **kwds)\n",
      "  File \"C:\\Users\\tlsdu\\anaconda3\\envs\\mine\\lib\\site-packages\\tensorflow_core\\python\\eager\\function.py\", line 2363, in __call__\n",
      "    return graph_function._filtered_call(args, kwargs)  # pylint: disable=protected-access\n",
      "  File \"C:\\Users\\tlsdu\\anaconda3\\envs\\mine\\lib\\site-packages\\tensorflow_core\\python\\eager\\function.py\", line 1611, in _filtered_call\n",
      "    self.captured_inputs)\n",
      "  File \"C:\\Users\\tlsdu\\anaconda3\\envs\\mine\\lib\\site-packages\\tensorflow_core\\python\\eager\\function.py\", line 1692, in _call_flat\n",
      "    ctx, args, cancellation_manager=cancellation_manager))\n",
      "  File \"C:\\Users\\tlsdu\\anaconda3\\envs\\mine\\lib\\site-packages\\tensorflow_core\\python\\eager\\function.py\", line 545, in call\n",
      "    ctx=ctx)\n",
      "  File \"C:\\Users\\tlsdu\\anaconda3\\envs\\mine\\lib\\site-packages\\tensorflow_core\\python\\eager\\execute.py\", line 67, in quick_execute\n",
      "    six.raise_from(core._status_to_exception(e.code, message), None)\n",
      "  File \"<string>\", line 3, in raise_from\n",
      "tensorflow.python.framework.errors_impl.UnknownError:  Failed to get convolution algorithm. This is probably because cuDNN failed to initialize, so try looking to see if a warning log message was printed above.\n",
      "\t [[node res_net/conv2d/Conv2D (defined at \\AppData\\Local\\Temp\\ipykernel_12152\\2408022449.py:47) ]] [Op:__inference_distributed_function_22855]\n",
      "\n",
      "Errors may have originated from an input operation.\n",
      "Input Source operations connected to node res_net/conv2d/Conv2D:\n",
      " Cast (defined at \\AppData\\Local\\Temp\\ipykernel_12152\\567259730.py:2)\n",
      "\n",
      "Function call stack:\n",
      "distributed_function\n",
      "\n",
      "\n",
      "During handling of the above exception, another exception occurred:\n",
      "\n",
      "Traceback (most recent call last):\n",
      "  File \"C:\\Users\\tlsdu\\anaconda3\\envs\\mine\\lib\\site-packages\\IPython\\core\\interactiveshell.py\", line 2077, in showtraceback\n",
      "    stb = value._render_traceback_()\n",
      "AttributeError: 'UnknownError' object has no attribute '_render_traceback_'\n",
      "\n",
      "During handling of the above exception, another exception occurred:\n",
      "\n",
      "Traceback (most recent call last):\n",
      "  File \"C:\\Users\\tlsdu\\anaconda3\\envs\\mine\\lib\\site-packages\\IPython\\core\\interactiveshell.py\", line 3377, in run_ast_nodes\n",
      "    if (await self.run_code(code, result,  async_=asy)):\n",
      "  File \"C:\\Users\\tlsdu\\anaconda3\\envs\\mine\\lib\\site-packages\\IPython\\core\\interactiveshell.py\", line 3474, in run_code\n",
      "    self.showtraceback(running_compiled_code=True)\n",
      "  File \"C:\\Users\\tlsdu\\anaconda3\\envs\\mine\\lib\\site-packages\\IPython\\core\\interactiveshell.py\", line 2080, in showtraceback\n",
      "    value, tb, tb_offset=tb_offset)\n",
      "  File \"C:\\Users\\tlsdu\\anaconda3\\envs\\mine\\lib\\site-packages\\IPython\\core\\ultratb.py\", line 1368, in structured_traceback\n",
      "    self, etype, value, tb, tb_offset, number_of_lines_of_context)\n",
      "  File \"C:\\Users\\tlsdu\\anaconda3\\envs\\mine\\lib\\site-packages\\IPython\\core\\ultratb.py\", line 1268, in structured_traceback\n",
      "    self, etype, value, tb, tb_offset, number_of_lines_of_context\n",
      "  File \"C:\\Users\\tlsdu\\anaconda3\\envs\\mine\\lib\\site-packages\\IPython\\core\\ultratb.py\", line 1125, in structured_traceback\n",
      "    tb_offset)\n",
      "  File \"C:\\Users\\tlsdu\\anaconda3\\envs\\mine\\lib\\site-packages\\IPython\\core\\ultratb.py\", line 1082, in format_exception_as_a_whole\n",
      "    last_unique, recursion_repeat = find_recursion(orig_etype, evalue, records)\n",
      "  File \"C:\\Users\\tlsdu\\anaconda3\\envs\\mine\\lib\\site-packages\\IPython\\core\\ultratb.py\", line 382, in find_recursion\n",
      "    return len(records), 0\n",
      "TypeError: object of type 'NoneType' has no len()\n",
      "\n",
      "During handling of the above exception, another exception occurred:\n",
      "\n",
      "Traceback (most recent call last):\n",
      "  File \"C:\\Users\\tlsdu\\anaconda3\\envs\\mine\\lib\\site-packages\\IPython\\core\\interactiveshell.py\", line 2077, in showtraceback\n",
      "    stb = value._render_traceback_()\n",
      "AttributeError: 'TypeError' object has no attribute '_render_traceback_'\n",
      "\n",
      "During handling of the above exception, another exception occurred:\n",
      "\n",
      "Traceback (most recent call last):\n",
      "  File \"C:\\Users\\tlsdu\\anaconda3\\envs\\mine\\lib\\site-packages\\IPython\\core\\interactiveshell.py\", line 2960, in _run_cell\n",
      "    return runner(coro)\n",
      "  File \"C:\\Users\\tlsdu\\anaconda3\\envs\\mine\\lib\\site-packages\\IPython\\core\\async_helpers.py\", line 78, in _pseudo_sync_runner\n",
      "    coro.send(None)\n",
      "  File \"C:\\Users\\tlsdu\\anaconda3\\envs\\mine\\lib\\site-packages\\IPython\\core\\interactiveshell.py\", line 3186, in run_cell_async\n",
      "    interactivity=interactivity, compiler=compiler, result=result)\n",
      "  File \"C:\\Users\\tlsdu\\anaconda3\\envs\\mine\\lib\\site-packages\\IPython\\core\\interactiveshell.py\", line 3396, in run_ast_nodes\n",
      "    self.showtraceback()\n",
      "  File \"C:\\Users\\tlsdu\\anaconda3\\envs\\mine\\lib\\site-packages\\IPython\\core\\interactiveshell.py\", line 2080, in showtraceback\n",
      "    value, tb, tb_offset=tb_offset)\n",
      "  File \"C:\\Users\\tlsdu\\anaconda3\\envs\\mine\\lib\\site-packages\\IPython\\core\\ultratb.py\", line 1368, in structured_traceback\n",
      "    self, etype, value, tb, tb_offset, number_of_lines_of_context)\n",
      "  File \"C:\\Users\\tlsdu\\anaconda3\\envs\\mine\\lib\\site-packages\\IPython\\core\\ultratb.py\", line 1268, in structured_traceback\n",
      "    self, etype, value, tb, tb_offset, number_of_lines_of_context\n",
      "  File \"C:\\Users\\tlsdu\\anaconda3\\envs\\mine\\lib\\site-packages\\IPython\\core\\ultratb.py\", line 1143, in structured_traceback\n",
      "    chained_exceptions_tb_offset)\n",
      "  File \"C:\\Users\\tlsdu\\anaconda3\\envs\\mine\\lib\\site-packages\\IPython\\core\\ultratb.py\", line 1082, in format_exception_as_a_whole\n",
      "    last_unique, recursion_repeat = find_recursion(orig_etype, evalue, records)\n",
      "  File \"C:\\Users\\tlsdu\\anaconda3\\envs\\mine\\lib\\site-packages\\IPython\\core\\ultratb.py\", line 382, in find_recursion\n",
      "    return len(records), 0\n",
      "TypeError: object of type 'NoneType' has no len()\n",
      "\n",
      "During handling of the above exception, another exception occurred:\n",
      "\n",
      "Traceback (most recent call last):\n",
      "  File \"C:\\Users\\tlsdu\\anaconda3\\envs\\mine\\lib\\site-packages\\IPython\\core\\interactiveshell.py\", line 2077, in showtraceback\n",
      "    stb = value._render_traceback_()\n",
      "AttributeError: 'TypeError' object has no attribute '_render_traceback_'\n",
      "\n",
      "During handling of the above exception, another exception occurred:\n",
      "\n",
      "Traceback (most recent call last):\n",
      "  File \"C:\\Users\\tlsdu\\anaconda3\\envs\\mine\\lib\\site-packages\\IPython\\core\\ultratb.py\", line 1101, in get_records\n",
      "    return _fixed_getinnerframes(etb, number_of_lines_of_context, tb_offset)\n",
      "  File \"C:\\Users\\tlsdu\\anaconda3\\envs\\mine\\lib\\site-packages\\IPython\\core\\ultratb.py\", line 248, in wrapped\n",
      "    return f(*args, **kwargs)\n",
      "  File \"C:\\Users\\tlsdu\\anaconda3\\envs\\mine\\lib\\site-packages\\IPython\\core\\ultratb.py\", line 281, in _fixed_getinnerframes\n",
      "    records = fix_frame_records_filenames(inspect.getinnerframes(etb, context))\n",
      "  File \"C:\\Users\\tlsdu\\anaconda3\\envs\\mine\\lib\\inspect.py\", line 1502, in getinnerframes\n",
      "    frameinfo = (tb.tb_frame,) + getframeinfo(tb, context)\n",
      "  File \"C:\\Users\\tlsdu\\anaconda3\\envs\\mine\\lib\\inspect.py\", line 1460, in getframeinfo\n",
      "    filename = getsourcefile(frame) or getfile(frame)\n",
      "  File \"C:\\Users\\tlsdu\\anaconda3\\envs\\mine\\lib\\inspect.py\", line 696, in getsourcefile\n",
      "    if getattr(getmodule(object, filename), '__loader__', None) is not None:\n",
      "  File \"C:\\Users\\tlsdu\\anaconda3\\envs\\mine\\lib\\inspect.py\", line 733, in getmodule\n",
      "    if ismodule(module) and hasattr(module, '__file__'):\n",
      "  File \"C:\\Users\\tlsdu\\anaconda3\\envs\\mine\\lib\\site-packages\\tensorflow\\__init__.py\", line 50, in __getattr__\n",
      "    module = self._load()\n",
      "  File \"C:\\Users\\tlsdu\\anaconda3\\envs\\mine\\lib\\site-packages\\tensorflow\\__init__.py\", line 44, in _load\n",
      "    module = _importlib.import_module(self.__name__)\n",
      "  File \"C:\\Users\\tlsdu\\anaconda3\\envs\\mine\\lib\\importlib\\__init__.py\", line 127, in import_module\n",
      "    return _bootstrap._gcd_import(name[level:], package, level)\n",
      "  File \"<frozen importlib._bootstrap>\", line 1006, in _gcd_import\n",
      "  File \"<frozen importlib._bootstrap>\", line 983, in _find_and_load\n",
      "  File \"<frozen importlib._bootstrap>\", line 965, in _find_and_load_unlocked\n",
      "ModuleNotFoundError: No module named 'tensorflow_core.estimator'\n"
     ]
    }
   ],
   "source": [
    "model.compile(optimizer=Adam(learning_rate=0.01),loss='categorical_crossentropy',metrics=['accuracy'])\n",
    "history = model.fit(train_x, train_y, epochs=50, batch_size=32,validation_data=(validation_x, validation_y))"
   ]
  },
  {
   "cell_type": "code",
   "execution_count": null,
   "id": "872450e9",
   "metadata": {},
   "outputs": [],
   "source": []
  }
 ],
 "metadata": {
  "kernelspec": {
   "display_name": "[2.1]",
   "language": "python",
   "name": "tfgpu2"
  },
  "language_info": {
   "codemirror_mode": {
    "name": "ipython",
    "version": 3
   },
   "file_extension": ".py",
   "mimetype": "text/x-python",
   "name": "python",
   "nbconvert_exporter": "python",
   "pygments_lexer": "ipython3",
   "version": "3.7.16"
  }
 },
 "nbformat": 4,
 "nbformat_minor": 5
}
